<?xml version="1.0" ?>
<robot name="indy" xmlns:xacro="http://www.ros.org/wiki/xacro">
<xacro:include filename="$(find indy)/urdf/gazebo_xacro.urdf"/>


<link name="foot_print"/>

<link name="bottle">
<visual>
    <origin xyz="0 0 0" rpy="0 0 0"/>
    <geometry>
        <cylinder length="0.02" radius="0.35"/>
    </geometry>
    <material name="dark_gray">
        <color rgba="0.2 0.2 0.2 1.0"/>
    </material>
</visual>
<collision>
    <origin xyz="0 0 0" rpy="0 0 0"/>
    <geometry>
        <cylinder length="0.02" radius="0.35"/>
    </geometry>
</collision>
<inertial>
    <origin xyz="0 0 0" rpy="0 0 0"/>
    <mass value="10"/>
    <inertia ixx="0" ixy="0.0" ixz="0.0" iyy="0" iyz="0.0" izz="0"/>
</inertial>
</link>

<link name="f_cy">
<visual>
    <origin xyz="0 0 0" rpy="0 0 0"/>
    <geometry>
        <cylinder length="0.25" radius="0.1"/>
    </geometry>
    <material name="gray">
        <color rgba="0.5 0.5 0.5 1.0"/>
    </material>
</visual>
<collision>
    <origin xyz="0 0 0" rpy="0 0 0"/>
    <geometry>
        <cylinder length="0.02" radius="0.35"/>
    </geometry>
</collision>
<inertial>
    <origin xyz="0 0 0" rpy="0 0 0"/>
    <mass value="8.3"/>
    <inertia ixx="0.2544" ixy="0.0" ixz="0.0" iyy="0.2544" iyz="0.0" izz="0.508"/>
</inertial>
</link>

<link name="s_cy">
<visual>
    <origin xyz="0 0 0" rpy="1.57 0 0"/>
    <geometry>
        <cylinder length="0.425" radius="0.1"/>
    </geometry>
    <material name="gray">
        <color rgba="0.5 0.5 0.5 1.0"/>
    </material>
</visual>
<collision>
    <origin xyz="0 0 0" rpy="0 0 0"/>
    <geometry>
        <cylinder length="0.02" radius="0.35"/>
    </geometry>
</collision>
<inertial>
    <origin xyz="0 0 0" rpy="0 0 0"/>
    <mass value="3.7"/>
    <inertia ixx="0.36" ixy="0.0" ixz="0.0" iyy="0.36" iyz="0.0" izz="0.2266"/>
</inertial>
</link>

<link name="t_cy">
<visual>
    <origin xyz="0 0 0" rpy="0 0 0"/>
    <geometry>
        <cylinder length="0.425" radius="0.1"/>
    </geometry>
    <material name="gray">
        <color rgba="0.5 0.5 0.5 1.0"/>
    </material>
</visual>
<collision>
    <origin xyz="0 0 0" rpy="0 0 0"/>
    <geometry>
        <cylinder length="0.02" radius="0.35"/>
    </geometry>
</collision>
<inertial>
    <origin xyz="0 0 0" rpy="0 0 0"/>
    <mass value="2.27"/>
    <inertia ixx="0.0002" ixy="0.0" ixz="0.0" iyy="0.0002" iyz="0.0" izz="0.0003"/>
</inertial>
</link>

<link name="four_cy">
<visual>
    <origin xyz="0 0 0" rpy="1.57 0 0"/>
    <geometry>
        <cylinder length="0.425" radius="0.1"/>
    </geometry>
    <material name="gray">
        <color rgba="0.5 0.5 0.5 1.0"/>
    </material>
</visual>
<collision>
    <origin xyz="0 0 0" rpy="0 0 0"/>
    <geometry>
        <cylinder length="0.02" radius="0.35"/>
    </geometry>
</collision>
<inertial>
    <origin xyz="0 0 0" rpy="0 0 0"/>
    <mass value="1.21"/>
    <inertia ixx="0.037" ixy="0.0" ixz="0.0" iyy="0.037" iyz="0.0" izz="0.07411"/>
</inertial>
</link>

<link name="five_cy">
<visual>
    <origin xyz="0 0 0" rpy="0 0 0"/>
    <geometry>
        <cylinder length="0.425" radius="0.1"/>
    </geometry>
    <material name="gray">
        <color rgba="0.5 0.5 0.5 1.0"/>
    </material>
</visual>
<collision>
    <origin xyz="0 0 0" rpy="0 0 0"/>
    <geometry>
        <cylinder length="0.02" radius="0.35"/>
    </geometry>
</collision>
<inertial>
    <origin xyz="0 0 0" rpy="0 0 0"/>
    <mass value="1.21"/>
    <inertia ixx="0.03709" ixy="0.0" ixz="0.0" iyy="0.03709" iyz="0.0" izz="0.0741"/>
</inertial>
</link>

<link name="six_cy">
<visual>
    <origin xyz="0 0 0" rpy="1.57 0 0"/>
    <geometry>
        <cylinder length="0.425" radius="0.1"/>
    </geometry>
    <material name="gray">
        <color rgba="0.5 0.5 0.5 1.0"/>
    </material>
</visual>
<collision>
    <origin xyz="0 0 0" rpy="0 0 0"/>
    <geometry>
        <cylinder length="0.02" radius="0.35"/>
    </geometry>
</collision>
<inertial>
    <origin xyz="0 0 0" rpy="0 0 0"/>
    <mass value="0.18"/>
    <inertia ixx="0.0055" ixy="0.0" ixz="0.0" iyy="0.0055" iyz="0.0" izz="0.011"/>
</inertial>
</link>

<link name="seven_cy">
<visual>
    <origin xyz="0 0 0" rpy="0 0 0"/>
    <geometry>
        <cylinder length="0.425" radius="0.1"/>
    </geometry>
    <material name="gray">
        <color rgba="0.5 0.5 0.5 1.0"/>
    </material>
</visual>
<collision>
    <origin xyz="0 0 0" rpy="0 0 0"/>
    <geometry>
        <cylinder length="0.02" radius="0.35"/>
    </geometry>
</collision>
<inertial>
    <origin xyz="0 0 0" rpy="0 0 0"/>
    <mass value="0.01"/>
    <inertia ixx="0" ixy="0" ixz="0" iyy="0" iyz="0" izz="0"/>
</inertial>
</link>




<joint name="foot_print_joint" type="fixed">
     <origin xyz="0 0 0" rpy="0 0 0" />
     <parent link="foot_print"/>
     <child link="bottle"/>
</joint>

<!-- <transmission name="fj_tran">
<type>transmission_interface/SimpleTransmission</type> -->
<joint name="f_joint" type="continuous">
<parent link="bottle"/>
<child link="f_cy"/>
<origin xyz="0 0 0.125" rpy="0 0 0" />
<axis xyz="0 0 1"/>
<!-- <hardwareInterface>hardware_interface/EffortJointInterface</hardwareInterface>
<mechanicalReduction>1</mechanicalReduction> -->
</joint>
<!-- <actuator name="fj_motor">
<hardwareInterface>hardware_interface/EffortJointInterface</hardwareInterface>
<mechanicalReduction>1</mechanicalReduction>
</actuator>
</transmission> -->
<!-- 
<transmission name="sj_tran">
<type>transmission_interface/SimpleTransmission</type> -->
<joint name="s_joint" type="continuous">
<parent link="f_cy"/>
<child link="s_cy"/>
<origin xyz="0 0.1115 0.125" rpy="0 0 0" />
<axis xyz="0 1 0"/>
<!-- <hardwareInterface>hardware_interface/EffortJointInterface</hardwareInterface>
<mechanicalReduction>1</mechanicalReduction> -->
</joint>
<!-- <actuator name="sj_motor"> -->
<!-- <hardwareInterface>hardware_interface/EffortJointInterface</hardwareInterface>
<mechanicalReduction>1</mechanicalReduction>
</actuator>
</transmission> -->

<!-- <transmission name="tj_tran">
<type>transmission_interface/SimpleTransmission</type> -->
<joint name="t_joint" type="continuous">
<parent link="s_cy"/>
<child link="t_cy"/>
<origin xyz="0 0.1115 0.125" rpy="0 0 0" />
<axis xyz="0 0 1"/>
<!-- <hardwareInterface>hardware_interface/EffortJointInterface</hardwareInterface>
<mechanicalReduction>1</mechanicalReduction> -->
</joint>
<!-- <actuator name="tj_motor">
<hardwareInterface>hardware_interface/EffortJointInterface</hardwareInterface>
<mechanicalReduction>1</mechanicalReduction>
</actuator>
</transmission> -->

<!-- <transmission name="foj_tran">
<type>transmission_interface/SimpleTransmission</type> -->
<joint name="four_joint" type="continuous">
<parent link="t_cy"/>
<child link="four_cy"/>
<origin xyz="0 -0.1115 0.125" rpy="0 0 0" />
<axis xyz="0 1 0"/>
<!-- <hardwareInterface>hardware_interface/EffortJointInterface</hardwareInterface>
<mechanicalReduction>1</mechanicalReduction> -->
</joint>
<!-- <actuator name="foj_motor"> -->
<!-- <hardwareInterface>hardware_interface/EffortJointInterface</hardwareInterface>
<mechanicalReduction>1</mechanicalReduction>
</actuator>
</transmission> -->

<!-- <transmission name="fij_tran">
<type>transmission_interface/SimpleTransmission</type> -->
<joint name="five_joint" type="continuous">
<parent link="four_cy"/>
<child link="five_cy"/>
<origin xyz="0 -0.1115 0.125" rpy="0 0 0" />
<axis xyz="0 0 1"/>
<!-- <hardwareInterface>hardware_interface/EffortJointInterface</hardwareInterface>
<mechanicalReduction>1</mechanicalReduction> -->
</joint>
<!-- <actuator name="fij_motor"> -->
<!-- <hardwareInterface>hardware_interface/EffortJointInterface</hardwareInterface>
<mechanicalReduction>1</mechanicalReduction>
</actuator>
</transmission> -->

<!-- <transmission name="sij_tran">
<type>transmission_interface/SimpleTransmission</type> -->
<joint name="six_joint" type="continuous">
<parent link="five_cy"/>
<child link="six_cy"/>
<origin xyz="0 -0.1115 0.125" rpy="0 0 0" />
<axis xyz="0 1 0"/>
<!-- <hardwareInterface>hardware_interface/EffortJointInterface</hardwareInterface>
<mechanicalReduction>1</mechanicalReduction> -->
</joint>
<actuator name="sij_motor">
<!-- <hardwareInterface>hardware_interface/EffortJointInterface</hardwareInterface>
<mechanicalReduction>1</mechanicalReduction>
</actuator>
</transmission> -->

<joint name="seven_joint" type="fixed">
<parent link="six_cy"/>
<child link="seven_cy"/>
<origin xyz="0 -0.1115 0.125" rpy="0 0 0" />
<axis xyz="0 1 0"/>
</joint>




</robot>


